Workbook

Sheet Read me
A1: What this workbook lists
A2: Three different collections are used in the EMS-Handoff evidence. They are often confused, so each has its own sheet.
A4: 1. Gold sample cases (4): hand-written radio reports (quick, STEMI, trauma, sepsis) with a hand-made gold report each. Used by the test suite and the first scoring work on 2026-10-24/25. Sheet 'Gold sample cases'.
A5: 2. Real call sets (22): recordings from a public county EMS feed, grouped into patient calls (51 bursts, 1,869 s). Three of them (CS001, CS008, CS014; 9 bursts, 612 words) have a human reference transcript and a gold report; the other 19 have neither. Sheet 'Real call sets'.
A6: 3. Generated scripts (200): template-written radio reports with exact gold facts, read by one synthetic voice through the radio channel at five noise levels (1,000 clips). Split by script, stratified by call family: 140 train, 30 validation, 30 test. Every transcript row in the matrix is the 30 test scripts (150 clips); every report row is the 30 test scripts at clean and 5 dB (60 reports). The validation 30 were first scored on 2026-10-30. Sheet 'Generated scripts' (one row per script, with its text) and 'Split by family'.
A8: So: '4 golden traces' = the 4 sample cases; '22 calls' = the real call sets; '30' = the test split of the 200 generated scripts (and a second 30 held out for validation).
A10: Columns in 'Generated scripts': split = train / val / test; family = the call type the template came from; priority and ETA are the values the script states (blank = not stated); gold fields = facts the scorer checks for that script; of which 'not stated' = fields whose correct answer is null (abstain); text = the script the voice read, which is also the transcript reference.
A11: Source files: ~/datasets/synth_v1/{index.tsv, splits.json, gold/, scripts/}; ~/callsets/<CS>/callset_info.json; ~/labels/{reference,gold}; tests/gold; ems_handoff/samples.py. Scoring definitions: docs/reports/SCORING_DEFINITIONS.md.

Sheet Generated scripts
A1: id | B1: split | C1: family | D1: alert_type | E1: priority (stated) | F1: ETA min (stated) | G1: words | H1: unit | I1: hospital | J1: alert words | K1: gold fields | L1: of which not stated | M1: text
A2: SY001 | B2: train | C2: fragment | D2: UNCLEAR | F2: 8 | G2: 8 | H2: Unit 40 | I2: White Oak | K2: 10 | L2: 8 | M2: White Oak, Unit 40. Updated ETA 8 minutes.
A3: SY002 | B3: train | C3: endocrine | D3: ENDOCRINE | E3: 2 | G3: 90 | H3: Medic 723 | I3: Holy Cross | J3: hypoglycemia | K3: 21 | L3: 6 | M3: Medic 723 to Holy Cross with a patient report. We're en route to your facility with a 23-year-old male, hypoglycemia, priority two. How do you copy so far? Family found the patient combative, initial blood glucose 30. Vitals: blood pressure 108/55, rate of 98, resp rate 31, SpO2 98%, and blood sugar 128. We administered 15 grams oral glucose PO, repeat glucose is 128 and the patient is now alert and oriented. History of type 2 diabetes and type 1 diabetes. Patient is on insulin. Any questions for Medic 723?
A4: SY003 | B4: train | C4: chest_pain | D4: MEDICAL | E4: 2 | G4: 94 | H4: Ambulance 716 | I4: Germantown | J4: chest pain | K4: 23 | L4: 5 | M4: Germantown, Ambulance 716. Priority two, 36-year-old female, chest pain. How do you copy? Patient woke up this morning with chest pain and upper back pain. Current vitals are as follows: pressure 174/79, rate of 103, sinus tach, respirations 21, and SpO2 96% on 6 liters nasal cannula. 12-lead is unremarkable. Patient is alert and oriented times four. 22-gauge IV in the left hand, saline lock. We administered 324 mg aspirin chewed. Medical history of CAD and anxiety. Medications include metformin, lisinopril, and Eliquis. NKDA. Family states patient is a full code. Ambulance 716 clear.
A5: SY004 | B5: train | C5: stroke | D5: STROKE | E5: 1 | F5: 10 | G5: 90 | H5: Unit 33 | I5: Sibley | J5: stroke, CVA, facial droop | K5: 21 | L5: 6 | M5: Good morning, Sibley, this is Unit 33. Inbound with a 57-year-old male, chief complaint stroke alert, priority one. Last known well about 30 minutes ago. Patient has right arm drift and right facial droop, speech is slurred. Current vitals are as follows: BP 171/115, pulse 92, AFib, respirations 18, sat of 97% on 4 liters nasal cannula, and blood glucose 126. Cincinnati is positive, two out of three. Grips weaker on the right. Requesting a stroke alert. We'll be at your facility in about 10 minutes. How do you copy?
A6: SY005 | B6: val | C6: chest_pain | D6: MEDICAL | E6: 3 | F6: 15 | G6: 78 | H6: Ambulance 702 | I6: Holy Cross | J6: chest pain | K6: 22 | L6: 7 | M6: Holy Cross, Ambulance 702. Inbound with a 54-year-old male, chief complaint chest pain, priority three, approximately 15 minutes out. Patient woke up this morning with chest pain and nausea. Vitals on scene: pressure 178/82, rate of 134, respiratory rate 17, and satting at 95% on room air. 12-lead shows sinus tach with no ST elevation. Lungs clear bilaterally. We've established a 22-gauge IV left hand. We administered 324 mg aspirin. Notification only, no orders needed. Ambulance 702 clear.
A7: SY006 | B7: val | C7: trauma | D7: TRAUMA | E7: 2 | F7: 8 | G7: 103 | H7: Unit 31 | I7: Germantown | J7: motorcycle | K7: 22 | L7: 3 | M7: Germantown online, this is Unit 31. We have a 16-year-old female, motorcycle crash, helmeted, priority two. Loss of consciousness unknown. Vitals on scene: pressure 124/66, heart rate 101, resp rate 24 and labored, and satting at 93%. GCS is 14, eyes 4, verbal 4, motor 6. Injuries include a right ankle deformity. Patient is c-spine immobilized on a backboard. Breath sounds bilateral but diminished on the right. Administered 4 mg ondansetron IV. Medical history of diabetes and AFib. No known allergies. Patient is DNR DNI per paperwork. Requesting trauma activation. We'll be at your facility in about 8 minutes. How do you copy?
A8: SY007 | B8: train | C8: trauma | D8: TRAUMA | E8: 2 | F8: 8 | G8: 115 | H8: Medic 41 | I8: County General | J8: motorcycle | K8: 22 | L8: 4 | M8: Medic 41 to County General with a patient report. We're en route to your facility with a 79-year-old female, motorcycle crash, helmeted, priority two. How do you copy so far? Vitals are pressure 102/58, heart rate 104, respiratory rate 29 and labored, and satting at 89% on 15 liters non-rebreather. GCS is 14, eyes 4, verbal 4, motor 6. Injuries include chest wall tenderness, a right ankle deformity, and left clavicle deformity. Patient extricated by fire, c-collar applied. Patient confused but following commands. Two large bore IVs established, running wide open. Administered 100 mcg fentanyl IV. History of diabetes. No known allergies. Requesting a trauma alert. We'll be at your facility in about 8 minutes.
A9: SY008 | B9: val | C9: pediatric | D9: PEDIATRIC | G9: 68 | H9: Squad 14 | I9: Fairfax | J9: pediatric, seizure | K9: 20 | L9: 8 | M9: Fairfax, Squad 14. We have a 7-year-old male, febrile seizure. Generalized seizure lasting approximately 5 minutes, witnessed by parents, resolved on our arrival. Patient is crying and consolable now. Vitals on scene: blood pressure 101/58, heart rate 147, satting at 94% on room air, temperature 102.8, and CBG 94. One prior febrile seizure. We administered 2 mg midazolam intranasal. No past medical history per family. Squad 14 clear.
A10: SY009 | B10: train | C10: sepsis | D10: SEPSIS | E10: 2 | F10: 8 | G10: 118 | H10: Medic 8 | I10: Fairfax | J10: sepsis, fever, altered mental status | K10: 22 | L10: 4 | M10: Fairfax, Medic 8 on the back line. We have a 88-year-old female, altered mental status and fever, priority two, approximately 8 minutes out. Patient is from home with hospice. Patient became increasingly confused and febrile. Vitals are blood pressure 92/50, heart rate 100, respiratory rate 22, SpO2 91% on 15 liters non-rebreather, and temp of 102.4. Skin is hot, dry and mottled at the knees. Suspected respiratory source, coarse rhonchi in the bilateral bases, productive cough. Lactate is 3.2. IV established, 22-gauge left forearm. 1000 mL of normal saline in so far. Medical history of CHF and hypertension. No known allergies. Family states patient is a full code. If you have no further questions, we'll see you shortly.
A11: SY010 | B11: train | C11: sepsis | D11: SEPSIS | E11: 2 | F11: 3 | G11: 109 | H11: Unit 37 | I11: Sibley | J11: sepsis, fever, altered mental status | K11: 22 | L11: 5 | M11: Sibley, Unit 37 on the back line. We have a 76-year-old female, possible sepsis, priority two. Per nursing staff, patient was at baseline until this morning. Patient became increasingly confused and febrile. Vitals are blood pressure 90/50, heart rate 124, respirations 26, sat of 92% on 6 liters nasal cannula, temp of 104.0, and blood sugar 215. Skin is warm and flushed. No obvious source. Lactate is 4.1. 18-gauge IV in the right hand, saline lock. 1000 mL of normal saline in so far. No past medical history per family. No known drug allergies. We're about 3 minutes out. If you have no further questions, we'll see you shortly.
A12: SY011 | B12: train | C12: chest_pain | D12: MEDICAL | E12: 2 | G12: 91 | H12: Ambulance 707 | I12: Shady Grove | J12: chest pain | K12: 24 | L12: 7 | M12: Good morning, Shady Grove, this is Ambulance 707. We have a 77-year-old female, chest pain, priority two. Patient woke up this morning with chest pain and shortness of breath. Vitals: pressure 129/100, rate of 69, normal sinus with PVCs, respirations 20, and satting at 94%. 12-lead is unremarkable. Currently complaining of 4 out of 10 chest pain. 20-gauge IV in the left AC, saline lock. We administered 324 mg aspirin chewed and 400 mcg nitro sublingual. Past medical history includes hyperlipidemia and hypertension. Allergies to morphine and latex. Ambulance 707 clear.
A13: SY012 | B13: train | C13: arrest | D13: CARDIAC_ARREST | E13: 1 | F13: 5 | G13: 85 | H13: Ambulance 711 | I13: Washington Adventist | J13: cardiac arrest, CPR, ROSC | K13: 21 | L13: 10 | M13: Washington Adventist, Ambulance 711. We're en route to your facility with a 43-year-old male, CPR in progress, priority one, approximately 5 minutes out. Witnessed arrest in a parking lot, CPR started by family. Initial rhythm asystole. CPR continues en route. Patient is intubated, tube confirmed with waveform capnography. CPR has been ongoing for 25 minutes. We have one round of epi. 18-gauge IV left AC. Patient has a history of hypertension, CAD, and ESRD on dialysis. No known drug allergies. Any questions for Ambulance 711?
A14: SY013 | B14: test | C14: chest_pain | D14: MEDICAL | E14: 2 | F14: 7 | G14: 95 | H14: Medic 33 | I14: Germantown | J14: chest pain | K14: 23 | L14: 6 | M14: Germantown, Medic 33. Priority two, 51-year-old female, chest pain. How do you copy? Patient woke up this morning with chest pain and palpitations. Vitals: blood pressure 119/71, heart rate 72, respirations 19, and satting at 96% on room air. 12-lead shows sinus tach with no ST elevation. Patient is alert and oriented times four. We've established a 22-gauge IV left hand. We administered 324 mg aspirin and 400 mcg nitro sublingual. No past medical history per family. No known drug allergies. Notification only, no orders needed. We'll be at your facility in about 7 minutes.
A15: SY014 | B15: test | C15: stroke | D15: STROKE | E15: 1 | F15: 8 | G15: 81 | H15: Paramedic 746 | I15: Riverside | J15: stroke, CVA, facial droop | K15: 20 | L15: 7 | M15: Good morning, Riverside, this is Paramedic 746. Priority one, 62-year-old female, stroke symptoms. How do you copy? Last known well about 60 minutes ago. Patient has right arm drift and right facial droop, speech is slurred. Current vitals are as follows: pressure 152/99, rate of 60, oxygen saturation 94% on room air, and blood sugar 151. LAMS is 5. Pupils equal and reactive. Medical history of CAD and AFib. Requesting a stroke alert. We're about 8 minutes out. Paramedic 746 clear.
A16: SY015 | B16: train | C16: sepsis | D16: SEPSIS | E16: 1 | F16: 5 | G16: 96 | H16: Unit 36 | I16: County General | J16: sepsis, fever, altered mental status | K16: 20 | L16: 5 | M16: County General, Unit 36 on the back line. Priority one, 86-year-old male, fever and hypotension. How do you copy? Family reports patient has been more confused for two days. Patient became increasingly confused and febrile. Vitals: BP 102/66, pulse 133, oxygen saturation 92% on 2 liters nasal cannula, and temperature 101.8. Skin is warm and flushed. Suspected skin source, a stage 4 sacral decubitus with foul drainage. Medical history of COPD, chronic kidney disease, and hypertension. Allergic to penicillin. Requesting a sepsis alert. Our ETA to your facility is approximately 5 minutes. How do you copy?
A17: SY016 | B17: train | C17: stemi | D17: STEMI | E17: 1 | F17: 10 | G17: 120 | H17: Unit 29 | I17: Washington Adventist | J17: STEMI, ST elevation, chest pain | K17: 25 | L17: 5 | M17: Washington Adventist, Unit 29 on the back line. We're en route to your facility with a 61-year-old female, chest pain, priority one, approximately 10 minutes out. Pain started about an hour ago, left-sided, radiating to the left arm. Vitals: blood pressure 169/78, heart rate 63, normal sinus, respiratory rate 24, and SpO2 96% on 6 liters nasal cannula. Patient is alert and oriented, diaphoretic. 12-lead shows ST elevation in leads II, III and aVF, consistent with inferior STEMI. Pain is 8 out of 10. We've established a 20-gauge IV left forearm. Administered 324 mg aspirin PO and 25 mcg fentanyl IV. Past medical history includes hypertension. NKDA. Requesting a STEMI alert and cath lab activation. Any questions for Unit 29?
A18: SY017 | B18: train | C18: chest_pain | D18: MEDICAL | E18: 2 | F18: 5 | G18: 97 | H18: Unit 25 | I18: Suburban | J18: chest pain | K18: 22 | L18: 7 | M18: Suburban, Unit 25. We have a 59-year-old male, chest pain, priority two. Patient was sitting on the couch around 8 PM when he began to feel substernal chest pain radiating to the jaw. Vitals on scene: pressure 118/84, pulse 81, resp rate 16, and SpO2 97% on room air. 12-lead shows sinus tach with no ST elevation. Currently complaining of 4 out of 10 chest pain. 22-gauge IV in the right AC, saline lock. We administered 0.4 mg nitro sublingual. No known drug allergies. ETA 5 minutes. If you have no further questions, we'll see you shortly.
A19: SY018 | B19: train | C19: stemi | D19: STEMI | E19: 2 | F19: 7 | G19: 128 | H19: Ambulance 727 | I19: Fairfax | J19: STEMI, ST elevation, chest pain | K19: 25 | L19: 5 | M19: Good evening, Fairfax, this is Ambulance 727. We have a 62-year-old female, chest pain, priority two. Pain started about two hours ago, substernal, radiating to the left shoulder. Vitals on scene: BP 112/66, pulse 106, sinus tach, respiratory rate 21, and satting at 93% on 4 liters nasal cannula. Patient is alert and oriented, diaphoretic. 12-lead shows ST elevation in leads V1 through V4, consistent with anterior STEMI. Pain is 7 out of 10. IV established, 20-gauge left forearm. Administered 324 mg aspirin chewed and 0.4 mg nitro sublingual times one. Some relief with the nitro. Medical history of prior MI. Allergies to contrast dye and sulfa. Requesting a STEMI alert and cath lab activation. Our ETA to your facility is approximately 7 minutes. How do you copy?
A20: SY019 | B20: train | C20: pediatric | D20: PEDIATRIC | E20: 1 | F20: 12 | G20: 63 | H20: Ambulance 710 | I20: White Oak | J20: pediatric, respiratory distress | K20: 21 | L20: 8 | M20: White Oak, Ambulance 710 on the back line. We're en route to your facility with a 20-month-old male, respiratory distress and trouble breathing, priority one, approximately 12 minutes out. Barky cough since this evening, retractions noted. Vitals are pressure 97/68, pulse 127, and oxygen saturation 87% on 15 liters non-rebreather. Patient is slightly altered but consolable. No known drug allergies. Ambulance 710 clear.
A21: SY020 | B21: train | C21: obstetric | D21: OBSTETRIC | E21: 2 | F21: 10 | G21: 106 | H21: Medic 8 | I21: Sibley | J21: pregnant, labor, delivery | K21: 22 | L21: 8 | M21: Medic 8 to Sibley, how do you copy? We're en route to your facility with a 20-year-old female, 36 weeks pregnant, possible pre-eclampsia, priority two. How do you copy so far? Patient is 36 weeks along, prenatal care at Fairfax. Severe headache, visual changes and swelling to the hands and face for two days. Vitals: blood pressure 174/103, pulse 122, and sat of 96%. Hyperreflexic, no seizure activity so far. Administered 4 grams magnesium IV. We've established a 20-gauge IV right forearm. No past medical history per family. Requesting labor and delivery be notified. Our ETA to your facility is approximately 10 minutes. Medic 8 clear.
A22: SY021 | B22: val | C22: stroke | D22: STROKE | E22: 1 | F22: 6 | G22: 77 | H22: Paramedic 717 | I22: Memorial | J22: stroke, CVA, facial droop | K22: 20 | L22: 7 | M22: Paramedic 717 to Memorial, how do you copy? We have a 71-year-old female, stroke symptoms, priority one, approximately 6 minutes out. Last known well last night at bedtime, found this way this morning. Family noticed left-sided facial droop and slurred speech. Vitals are blood pressure 206/115, heart rate 65, oxygen saturation 95%, and sugar is 118. LAMS is 4. Pupils equal and reactive. Allergies to penicillin and morphine. Requesting stroke team activation. Any questions for Paramedic 717?
A23: SY022 | B23: train | C23: trauma | D23: TRAUMA | E23: 3 | F23: 3 | G23: 117 | H23: Medic 15 | I23: White Oak | J23: assault | K23: 23 | L23: 5 | M23: White Oak, Medic 15. We're en route to your facility with a 46-year-old male, assault with a blunt object to the head, priority three. How do you copy so far? Loss of consciousness unknown. Vitals are BP 98/67, rate of 127, respiratory rate 20 and shallow, and sat of 96% on room air. GCS is 15. Injuries include epistaxis, a laceration above the left eye, and a large hematoma to the left temple. Patient is c-spine immobilized on a backboard. Pupils equal and reactive. We have two large bore IVs, fluids running wide open. Administered 100 mcg fentanyl IV and 1 gram TXA IV. Allergic to latex. Requesting a trauma alert. ETA 3 minutes. Medic 15 clear.
A24: SY023 | B24: train | C24: trauma | D24: TRAUMA | E24: 1 | F24: 8 | G24: 99 | H24: Medic 28 | I24: Riverside | J24: MVC | K24: 22 | L24: 5 | M24: Good afternoon, Riverside, this is Medic 28. Priority one, 25-year-old female, MVC, unrestrained passenger, significant front end damage. How do you copy? Positive loss of consciousness at scene per bystanders. Vitals: BP 116/88, heart rate 81, respiratory rate 20 and labored, and SpO2 93% on 2 liters nasal cannula. GCS is 8. Injuries include deformity to the right forearm and left femur deformity. Patient confused but following commands. 20-gauge IV in the left hand, saline lock. Administered 50 mcg fentanyl IV. No known allergies. Patient is DNR DNI per paperwork. Our ETA to your facility is approximately 8 minutes.
A25: SY024 | B25: test | C25: stroke | D25: STROKE | E25: 2 | G25: 101 | H25: Unit 31 | I25: Holy Cross | J25: stroke, CVA, facial droop | K25: 21 | L25: 4 | M25: Holy Cross, Unit 31 on the back line. Inbound with a 76-year-old female, chief complaint stroke symptoms, priority two. Last known well about 30 minutes ago. Family noticed left-sided facial droop and slurred speech. Vitals on scene: blood pressure 153/103, heart rate 58, respiratory rate 14, sat of 99% on room air, and blood glucose 90. Cincinnati stroke scale positive for arm drift and speech. No trauma noted. We've established an 18-gauge IV right AC. No medications given. History of hypertension and CAD. Patient is on warfarin, metformin, and lisinopril. Family states patient is a full code. Requesting stroke team activation.
A26: SY025 | B26: train | C26: endocrine | D26: ENDOCRINE | E26: 2 | F26: 20 | G26: 68 | H26: Paramedic 740 | I26: Sibley | J26: DKA, hyperglycemia | K26: 20 | L26: 6 | M26: Sibley, Paramedic 740. Inbound with a 29-year-old female, chief complaint possible DKA, priority two. Patient ran out of insulin three days ago. Patient is alert but lethargic, skin dry. Vitals on scene: pressure 107/63, pulse 99, resp rate 23, satting at 96%, and sugar is 560. Past medical history includes hypothyroidism and hypertension. Medications include insulin, Lantus, and metformin. See you in approximately 20 minutes. Paramedic 740 clear.
A27: SY026 | B27: train | C27: fragment | D27: UNCLEAR | F27: 15 | G27: 11 | H27: Ambulance 706 | I27: Washington Adventist | K27: 10 | L27: 8 | M27: Washington Adventist, Ambulance 706. Be advised we are 15 minutes out.
A28: SY027 | B28: val | C28: sepsis | D28: SEPSIS | E28: 1 | F28: 15 | G28: 112 | H28: Paramedic 709 | I28: Sibley | J28: sepsis, fever, altered mental status | K28: 22 | L28: 3 | M28: Good morning, Sibley, this is Paramedic 709. Priority one, 77-year-old male, altered mental status and fever., approximately 15 minutes out. Family reports patient has been more confused for two days. Patient became increasingly confused and febrile. Vitals: BP 97/52, pulse 114, respiratory rate 25, oxygen saturation 95% on 2 liters nasal cannula, and temp of 100.9. Patient oriented to name only. Suspected urinary source, foley catheter in place, urine appears cloudy. We've established an 18-gauge IV left AC. 1000 mL of normal saline in so far. Patient has a history of CHF and chronic kidney disease. Home meds are furosemide. Allergic to codeine. We're calling a sepsis alert. How do you copy?
A29: SY028 | B29: test | C29: stemi | D29: STEMI | F29: 20 | G29: 125 | H29: Medic 724 | I29: Riverside | J29: STEMI, ST elevation, chest pain | K29: 25 | L29: 5 | M29: Riverside, Medic 724. Inbound with a 57-year-old male, chief complaint chest pain. Patient was at home when the pain started approximately 45 minutes ago. Vitals are pressure 170/60, heart rate 73, normal sinus with PVCs, and oxygen saturation 97% on 4 liters nasal cannula. Skin is cool and diaphoretic. 12-lead shows ST elevation in leads V1 through V4, consistent with anterior STEMI. IV established, 18-gauge right AC. Administered 324 mg aspirin, 0.4 mg nitro sublingual times three, and 100 mcg fentanyl IV. Some relief with the nitro. History of hyperlipidemia, prior MI, and hypertension. Takes Plavix, atorvastatin, and metformin. No known drug allergies. Requesting a STEMI alert and cath lab activation. Our ETA to your facility is approximately 20 minutes. Any questions for Medic 724?
A30: SY029 | B30: train | C30: endocrine | D30: ENDOCRINE | E30: 2 | F30: 4 | G30: 71 | H30: Unit 36 | I30: Germantown | J30: hypoglycemia | K30: 21 | L30: 6 | M30: Germantown, Unit 36. Priority two, 45-year-old female, hypoglycemia. How do you copy? Family found the patient unresponsive, initial blood glucose 33. Current vitals are as follows: blood pressure 140/85, pulse 123, respiratory rate 19, sat of 97% on room air, and CBG 121. We administered 125 mL D10 IV, repeat glucose is 121 and the patient is now alert and oriented. NKDA. We're about 4 minutes out. How do you copy?
A31: SY030 | B31: val | C31: trauma | D31: TRAUMA | E31: 2 | F31: 5 | G31: 86 | H31: Unit 31 | I31: Memorial | J31: fall | K31: 22 | L31: 6 | M31: Good morning, Memorial, this is Unit 31. We have a 30-year-old male, fall from approximately 15 feet, priority two. No medical history available. Vitals are BP 119/89, pulse 98, resp rate 22, and oxygen saturation 98% on 2 liters nasal cannula. GCS is 14. Injuries include a laceration to the forehead and right hip pain with shortening and rotation. Patient extricated by fire, c-collar applied. Breath sounds bilateral but diminished on the right. Administered 100 mcg fentanyl IV. Requesting trauma activation. We're about 5 minutes out.
A32: SY031 | B32: train | C32: stemi | D32: STEMI | F32: 3 | G32: 127 | H32: Squad 4 | I32: Washington Adventist | J32: STEMI, ST elevation, chest pain | K32: 23 | L32: 5 | M32: Washington Adventist, Squad 4. We have a 69-year-old male, chest pain. Pain started about two hours ago, left-sided, radiating to the left arm. Vitals are pressure 126/99, heart rate 56 and irregular, respirations 23, and sat of 94% on 6 liters nasal cannula. Patient is diaphoretic and pale. 12-lead shows ST elevation in leads II, III and aVF, consistent with inferior STEMI. Pain is 5 out of 10. Administered 324 mg aspirin chewed and 0.4 mg nitro sublingual times one. Some relief with the nitro. History of prior MI, type 2 diabetes, and hyperlipidemia. Medications include amlodipine and aspirin 81. Requesting a STEMI alert and cath lab activation. We'll be at your facility in about 3 minutes. If you have no further questions, we'll see you shortly.
A33: SY032 | B33: train | C33: sepsis | D33: SEPSIS | E33: 1 | G33: 111 | H33: Paramedic 709 | I33: Sibley | J33: sepsis, fever, altered mental status | K33: 22 | L33: 3 | M33: Sibley online, this is Paramedic 709. Inbound with a 88-year-old female, chief complaint possible sepsis, priority one. Family reports patient has been more confused for two days. Patient became increasingly confused and febrile. Vitals on scene: blood pressure 101/60, pulse 109, respirations 29, SpO2 94% on 15 liters non-rebreather, temp of 101.8, and blood sugar 303. Patient oriented to name only. Suspected skin source, a stage 4 sacral decubitus with foul drainage. IV established, 22-gauge left forearm. Running a 500 mL bolus. Past medical history includes chronic kidney disease. Home meds are donepezil. Patient is full code. Requesting a sepsis alert. If you have no further questions, we'll see you shortly.
A34: SY033 | B34: train | C34: trauma | D34: TRAUMA | G34: 82 | H34: Squad 4 | I34: County General | J34: MVC | K34: 20 | L34: 8 | M34: County General, Squad 4. We have a 66-year-old male, MVC, unrestrained passenger, significant front end damage. Positive loss of consciousness at scene per bystanders. Current vitals are as follows: pressure 123/79, rate of 95, and oxygen saturation 90% on 15 liters non-rebreather. Injuries include left femur deformity, a large scalp laceration with controlled bleeding, and deformity to the right forearm. Patient is c-spine immobilized on a backboard. Pupils equal and reactive. No known allergies. Requesting a trauma alert. How do you copy?
A35: SY034 | B35: train | C35: pediatric | D35: PEDIATRIC | E35: 1 | F35: 4 | G35: 83 | H35: Paramedic 749 | I35: Fairfax | J35: pediatric, respiratory distress | K35: 22 | L35: 8 | M35: Paramedic 749 to Fairfax, how do you copy? We have a 17-month-old male, respiratory distress, priority one. Mom called because the patient was working harder to breathe with a lot of drool and a cough. Current vitals are as follows: blood pressure 90/50, heart rate 124, and SpO2 87% on 15 liters non-rebreather. Stridor at rest. We administered 2.5 mg albuterol nebulized. Patient has a history of prematurity. We're about 4 minutes out. If you have no further questions, we'll see you shortly.
A36: SY035 | B36: train | C36: pediatric | D36: PEDIATRIC | E36: 1 | F36: 8 | G36: 76 | H36: Medic 17 | I36: Memorial | J36: pediatric, respiratory distress | K36: 21 | L36: 6 | M36: Memorial online, this is Medic 17. Priority one, 7-year-old female, respiratory distress. How do you copy? Audible wheezing, mom states a history of asthma. Vitals on scene: pressure 92/50, pulse 135, respirations 37, and sat of 92% on blow-by oxygen. Wheezes bilaterally. We administered 2.5 mg albuterol nebulized, with some improvement. Patient has a history of asthma and seizure disorder. Allergies to sulfa and shellfish. See you in approximately 8 minutes. Any questions for Medic 17?
A37: SY036 | B37: train | C37: stemi | D37: STEMI | E37: 1 | F37: 6 | G37: 117 | H37: Unit 21 | I37: County General | J37: STEMI, ST elevation, chest pain | K37: 25 | L37: 7 | M37: County General online, this is Unit 21. We have a 59-year-old female, chest pain, priority one. Pain started about an hour ago, substernal, radiating to the left arm. Vitals are BP 163/74, pulse 54 and irregular, respirations 21, and satting at 91% on room air. Skin is cool and diaphoretic. 12-lead shows ST elevation in leads V2 through V5, consistent with anterior STEMI. Pain is 5 out of 10. 20-gauge IV in the left AC, saline lock. Administered 324 mg aspirin and 0.4 mg nitro sublingual times one. Pain down to 4 out of 10 after the nitro. No medications. Requesting cath lab activation. ETA 6 minutes. If you have no further questions, we'll see you shortly.
A38: SY037 | B38: train | C38: medical | D38: MEDICAL | F38: 10 | G38: 79 | H38: Unit 41 | I38: Germantown | K38: 20 | L38: 6 | M38: Germantown, Unit 41 on the back line. 60-year-old male, generalized weakness. How do you copy? Generalized weakness for three days, poor oral intake, unable to stand without help. Vitals are pressure 128/82, rate of 83, respiratory rate 16, and SpO2 96% on room air. No focal deficits, Cincinnati negative. 22-gauge IV in the right forearm, saline lock. History of diabetes. Patient is a DNR. We're about 10 minutes out. If you have no further questions, we'll see you shortly.
A39: SY038 | B39: val | C39: fragment | D39: UNCLEAR | F39: 5 | G39: 13 | H39: Squad 8 | I39: Sibley | K39: 10 | L39: 7 | M39: Sibley, Squad 8. Correction, the patient is 62, not 72. ETA 5 minutes.
A40: SY039 | B40: train | C40: fragment | D40: STEMI | E40: 1 | F40: 5 | G40: 16 | H40: Unit 17 | I40: Sibley | J40: STEMI | K40: 11 | L40: 7 | M40: Sibley, Unit 17. STEMI, priority one, 49-year-old female, about 5 minutes out. How do you copy?
...

Sheet Split by family
A1: family | B1: train | C1: val | D1: test | E1: total
A2: arrest | B2: =COUNTIFS('Generated scripts'!$C$2:$C$201,$A2,'Generated scripts'!$B$2:$B$201,"train") -> 7 | C2: =COUNTIFS('Generated scripts'!$C$2:$C$201,$A2,'Generated scripts'!$B$2:$B$201,"val") -> 2 | D2: =COUNTIFS('Generated scripts'!$C$2:$C$201,$A2,'Generated scripts'!$B$2:$B$201,"test") -> 2 | E2: =SUM(B2:D2) -> 11
A3: chest_pain | B3: =COUNTIFS('Generated scripts'!$C$2:$C$201,$A3,'Generated scripts'!$B$2:$B$201,"train") -> 11 | C3: =COUNTIFS('Generated scripts'!$C$2:$C$201,$A3,'Generated scripts'!$B$2:$B$201,"val") -> 2 | D3: =COUNTIFS('Generated scripts'!$C$2:$C$201,$A3,'Generated scripts'!$B$2:$B$201,"test") -> 2 | E3: =SUM(B3:D3) -> 15
A4: endocrine | B4: =COUNTIFS('Generated scripts'!$C$2:$C$201,$A4,'Generated scripts'!$B$2:$B$201,"train") -> 10 | C4: =COUNTIFS('Generated scripts'!$C$2:$C$201,$A4,'Generated scripts'!$B$2:$B$201,"val") -> 2 | D4: =COUNTIFS('Generated scripts'!$C$2:$C$201,$A4,'Generated scripts'!$B$2:$B$201,"test") -> 2 | E4: =SUM(B4:D4) -> 14
A5: fragment | B5: =COUNTIFS('Generated scripts'!$C$2:$C$201,$A5,'Generated scripts'!$B$2:$B$201,"train") -> 17 | C5: =COUNTIFS('Generated scripts'!$C$2:$C$201,$A5,'Generated scripts'!$B$2:$B$201,"val") -> 4 | D5: =COUNTIFS('Generated scripts'!$C$2:$C$201,$A5,'Generated scripts'!$B$2:$B$201,"test") -> 4 | E5: =SUM(B5:D5) -> 25
A6: medical | B6: =COUNTIFS('Generated scripts'!$C$2:$C$201,$A6,'Generated scripts'!$B$2:$B$201,"train") -> 13 | C6: =COUNTIFS('Generated scripts'!$C$2:$C$201,$A6,'Generated scripts'!$B$2:$B$201,"val") -> 3 | D6: =COUNTIFS('Generated scripts'!$C$2:$C$201,$A6,'Generated scripts'!$B$2:$B$201,"test") -> 3 | E6: =SUM(B6:D6) -> 19
A7: obstetric | B7: =COUNTIFS('Generated scripts'!$C$2:$C$201,$A7,'Generated scripts'!$B$2:$B$201,"train") -> 6 | C7: =COUNTIFS('Generated scripts'!$C$2:$C$201,$A7,'Generated scripts'!$B$2:$B$201,"val") -> 1 | D7: =COUNTIFS('Generated scripts'!$C$2:$C$201,$A7,'Generated scripts'!$B$2:$B$201,"test") -> 1 | E7: =SUM(B7:D7) -> 8
A8: pediatric | B8: =COUNTIFS('Generated scripts'!$C$2:$C$201,$A8,'Generated scripts'!$B$2:$B$201,"train") -> 10 | C8: =COUNTIFS('Generated scripts'!$C$2:$C$201,$A8,'Generated scripts'!$B$2:$B$201,"val") -> 2 | D8: =COUNTIFS('Generated scripts'!$C$2:$C$201,$A8,'Generated scripts'!$B$2:$B$201,"test") -> 2 | E8: =SUM(B8:D8) -> 14
A9: psychiatric | B9: =COUNTIFS('Generated scripts'!$C$2:$C$201,$A9,'Generated scripts'!$B$2:$B$201,"train") -> 7 | C9: =COUNTIFS('Generated scripts'!$C$2:$C$201,$A9,'Generated scripts'!$B$2:$B$201,"val") -> 1 | D9: =COUNTIFS('Generated scripts'!$C$2:$C$201,$A9,'Generated scripts'!$B$2:$B$201,"test") -> 1 | E9: =SUM(B9:D9) -> 9
A10: sepsis | B10: =COUNTIFS('Generated scripts'!$C$2:$C$201,$A10,'Generated scripts'!$B$2:$B$201,"train") -> 12 | C10: =COUNTIFS('Generated scripts'!$C$2:$C$201,$A10,'Generated scripts'!$B$2:$B$201,"val") -> 3 | D10: =COUNTIFS('Generated scripts'!$C$2:$C$201,$A10,'Generated scripts'!$B$2:$B$201,"test") -> 3 | E10: =SUM(B10:D10) -> 18
A11: stemi | B11: =COUNTIFS('Generated scripts'!$C$2:$C$201,$A11,'Generated scripts'!$B$2:$B$201,"train") -> 11 | C11: =COUNTIFS('Generated scripts'!$C$2:$C$201,$A11,'Generated scripts'!$B$2:$B$201,"val") -> 2 | D11: =COUNTIFS('Generated scripts'!$C$2:$C$201,$A11,'Generated scripts'!$B$2:$B$201,"test") -> 2 | E11: =SUM(B11:D11) -> 15
A12: stroke | B12: =COUNTIFS('Generated scripts'!$C$2:$C$201,$A12,'Generated scripts'!$B$2:$B$201,"train") -> 17 | C12: =COUNTIFS('Generated scripts'!$C$2:$C$201,$A12,'Generated scripts'!$B$2:$B$201,"val") -> 4 | D12: =COUNTIFS('Generated scripts'!$C$2:$C$201,$A12,'Generated scripts'!$B$2:$B$201,"test") -> 4 | E12: =SUM(B12:D12) -> 25
A13: trauma | B13: =COUNTIFS('Generated scripts'!$C$2:$C$201,$A13,'Generated scripts'!$B$2:$B$201,"train") -> 19 | C13: =COUNTIFS('Generated scripts'!$C$2:$C$201,$A13,'Generated scripts'!$B$2:$B$201,"val") -> 4 | D13: =COUNTIFS('Generated scripts'!$C$2:$C$201,$A13,'Generated scripts'!$B$2:$B$201,"test") -> 4 | E13: =SUM(B13:D13) -> 27
A14: total | B14: =SUM(B2:B13) -> 140 | C14: =SUM(C2:C13) -> 30 | D14: =SUM(D2:D13) -> 30 | E14: =SUM(E2:E13) -> 200
A16: Counts are formulas over the 'Generated scripts' sheet; splits.json: seed 1, stratified by family, 140 / 30 / 30.

Sheet Real call sets
A1: call set | B1: feed | C1: bursts | D1: audio s | E1: words | F1: first burst UTC | G1: complaint keywords | H1: reference transcript | I1: gold report | J1: appears truncated | K1: segments
A2: CS001 | B2: 4390 | C2: 3 | D2: 92 | E2: 132 | F2: 2026-10-23 21:41:07 | G2: stroke | H2: yes (3 bursts) | I2: yes | J2: end | K2: S044_01, S045_01, S046_01
A3: CS002 | B3: 4390 | C3: 2 | D3: 107 | E3: 207 | F3: 2026-10-23 22:26:18 | G3: respiratory | H3: no | I3: no | J3: no | K3: S042_01, S043_01
A4: CS003 | B4: 4390 | C4: 3 | D4: 33 | E4: 66 | F4: 2026-10-24 00:52:41 | H4: no | I4: no | J4: start | K4: S037_01, S039_01, S041_01
A5: CS004 | B5: 4395 | C5: 2 | D5: 111 | E5: 266 | F5: 2026-10-24 00:52:46 | G5: trauma | H5: no | I5: no | J5: end | K5: S038_01, S040_01
A6: CS005 | B6: 4390 | C6: 4 | D6: 82 | E6: 158 | F6: 2026-10-24 01:18:02 | G6: trauma | H6: no | I6: no | J6: start | K6: S033_01, S034_01, S035_01, S036_01
A7: CS006 | B7: 4390 | C7: 6 | D7: 79 | E7: 134 | F7: 2026-10-24 01:28:05 | G7: stroke | H7: no | I7: no | J7: no | K7: S027_01, S028_01, S029_01, S030_01, S031_01, S032_01
A8: CS007 | B8: 4390 | C8: 1 | D8: 31 | E8: 58 | F8: 2026-10-24 02:10:46 | G8: arrhythmia | H8: no | I8: no | J8: end | K8: S026_01
A9: CS008 | B9: 4390 | C9: 1 | D9: 84 | E9: 188 | F9: 2026-10-24 02:30:46 | G9: chest pain | H9: yes (1 bursts) | I9: yes | J9: no | K9: S025_01
A10: CS009 | B10: 4390 | C10: 1 | D10: 75 | E10: 201 | F10: 2026-10-24 02:42:16 | G10: refusal, trauma | H10: no | I10: no | J10: start+end | K10: S022_01
A11: CS010 | B11: 4390 | C11: 2 | D11: 77 | E11: 181 | F11: 2026-10-24 03:20:01 | G11: altered/glucose, stroke | H11: no | I11: no | J11: start+end | K11: S020_01, S021_01
A12: CS011 | B12: 4390 | C12: 1 | D12: 116 | E12: 299 | F12: 2026-10-24 03:47:58 | G12: trauma | H12: no | I12: no | J12: end | K12: S019_01
A13: CS012 | B13: 4390 | C13: 1 | D13: 55 | E13: 118 | F13: 2026-10-24 04:19:24 | G13: overdose | H13: no | I13: no | J13: start+end | K13: S018_01
A14: CS013 | B14: 4390 | C14: 2 | D14: 110 | E14: 163 | F14: 2026-10-24 04:23:17 | G14: seizure | H14: no | I14: no | J14: no | K14: S016_01, S017_01
A15: CS014 | B15: 4390 | C15: 5 | D15: 104 | E15: 234 | F15: 2026-10-24 07:41:02 | G15: altered/glucose, respiratory | H15: yes (5 bursts) | I15: yes | J15: no | K15: S054_01, S055_01, S013_01, S014_01, S015_01
A16: CS016 | B16: 4390 | C16: 2 | D16: 115 | E16: 227 | F16: 2026-10-24 12:33:02 | G16: trauma | H16: no | I16: no | J16: no | K16: S011_01, S012_01
A17: CS017 | B17: 4390 | C17: 1 | D17: 56 | E17: 110 | F17: 2026-10-24 13:14:29 | G17: altered/glucose, chest pain | H17: no | I17: no | J17: no | K17: S010_01
A18: CS018 | B18: 4390 | C18: 1 | D18: 3 | E18: 3 | F18: 2026-10-24 13:45:18 | H18: no | I18: no | J18: start+end | K18: S009_01
A19: CS019 | B19: 4390 | C19: 1 | D19: 74 | E19: 142 | F19: 2026-10-24 13:46:45 | G19: altered/glucose, stroke | H19: no | I19: no | J19: no | K19: S008_01
A20: CS020 | B20: 4390 | C20: 1 | D20: 59 | E20: 130 | F20: 2026-10-24 14:19:14 | G20: arrhythmia, chest pain | H20: no | I20: no | J20: no | K20: S007_01
A21: CS021 | B21: 4390 | C21: 7 | D21: 161 | E21: 396 | F21: 2026-10-24 16:38:32 | G21: altered/glucose, refusal | H21: no | I21: no | J21: no | K21: S047_01, S049_01, S050_01, S051_01, S052_01, S053_01, S002_01
A22: CS022 | B22: 4395 | C22: 1 | D22: 116 | E22: 228 | F22: 2026-10-24 16:38:37 | G22: stroke | H22: no | I22: no | J22: start | K22: S048_01
A23: CS023 | B23: 4395 | C23: 3 | D23: 132 | E23: 304 | F23: 2026-10-24 16:42:45 | G23: stroke, trauma | H23: no | I23: no | J23: no | K23: S001_01, S005_01, S003_01
A24: total | C24: =SUM(C2:C23) -> 51 | D24: =SUM(D2:D23) -> 1872 | E24: =SUM(E2:E23) -> 3945
A26: Per-burst transcripts (whisper) are in ~/callsets/<CS>/<segment>.txt; human references only for the three marked yes; gold reports in ~/labels/gold. Feed 4390 is the county EMS channel; 4430 a second feed joined on review.

Sheet Gold sample cases
A1: case | B1: title | C1: gold fields | D1: total weight | E1: of which not stated | F1: words | G1: text
A2: quick | B2: Quick demo (short) | C2: 19 | D2: 42 | E2: 7 | F2: 46 | G2: Medic 21 to General Hospital. We are inbound with a 45-year-old male found down. GCS is 14. History of seizures. Vitals: BP 140 over 90, heart rate 110, SpO2 98 percent. We have established an IV and given 5 milligrams of Versed. ETA is 5 minutes.
A3: stemi | B3: STEMI | C3: 22 | D3: 50 | E3: 2 | F3: 160 | G3: Unit 41 to Memorial Hospital, how do you copy? We're inbound with a 67-year-old male, chief complaint chest pain radiating to left arm. Patient was at home watching TV when symptoms started approximately 45 minutes ago. Wife called 911 when he became diaphoretic and short of breath. Vitals on scene: BP 158/92, heart rate 98 and irregular, respiratory rate 22, SpO2 94% on room air, now 98% on 4 liters nasal cannula. 12-lead shows ST elevation in leads V1 through V4, consistent with anterior STEMI. Patient has history of hypertension and type 2 diabetes. Takes metformin and lisinopril daily. No known allergies. We've established an 18-gauge IV left AC, administered 324mg aspirin chewed, and 0.4mg sublingual nitro times two with some relief. Currently running a saline lock. Patient is alert and oriented, pain currently 6 out of 10, down from 9 out of 10. Our ETA to your facility is approximately 8 minutes. Requesting cath lab activation. Unit 41 clear.
A4: trauma | B4: Trauma | C4: 21 | D4: 50 | E4: 4 | F4: 147 | G4: Medic 7 to County General trauma, priority traffic. Inbound with a 34-year-old female, restrained driver, high-speed MVC with rollover. Positive loss of consciousness at scene, approximately 2 minutes per bystanders. Patient was extricated by fire, c-spine immobilized, on backboard. Vitals: BP 88/60, heart rate 124, respiratory rate 28 and shallow, SpO2 91% on 15 liters non-rebreather. GCS is 13, eyes 3, verbal 4, motor 6. Pupils equal and reactive. Patient confused but following commands. Visible injuries include a large scalp laceration with controlled bleeding, deformity to right forearm likely fracture, and she's guarding her abdomen with bruising across lower quadrants consistent with seatbelt sign. Two large bore IVs established, running wide open. No medications administered. Bilateral breath sounds present but diminished on right. Patient is a visitor from out of state, no medical history available, no medications known, allergy status unknown. ETA 6 minutes, requesting trauma activation.
A5: sepsis | B5: Sepsis | C5: 19 | D5: 43 | E5: 0 | F5: 154 | G5: Squad 12 to Riverside Emergency. We have an 82-year-old female from Sunrise Nursing Facility, chief complaint altered mental status and fever. Per nursing staff, patient was in her usual state of dementia baseline until this morning when she became increasingly confused, not recognizing staff, and had a temperature of 102.4. Vitals: BP 92/58, heart rate 108, respiratory rate 24, SpO2 93% on 2 liters, blood glucose 186. Patient is oriented to name only, not following commands consistently. Skin is warm and flushed. Lungs have coarse rhonchi bilateral bases. History per facility transfer sheet: Alzheimer's dementia, CHF, atrial fibrillation, chronic kidney disease stage 3. Medications include metoprolol, furosemide, donepezil, and eliquis. Allergies to penicillin and sulfa drugs. She has a foley catheter in place, urine appears cloudy. IV established 20-gauge right hand, 500ml bolus initiated. No other interventions. Patient is DNR but full treatment per POLST form, which we have with us. ETA 12 minutes.
A7: Hand-written by the project on 2026-10-24; gold in tests/gold/<case>.json; scored by scripts/benchmark.py. These four were the first 'golden traces'; the generated scripts and real call sets came later.
